<sdf version='1.11'>
  <model name='robot'>
    <link name='base_link'>
      <inertial>
        <pose>0.065000000000000002 0 0.0625 0 0 0</pose>
        <mass>0.59999999999999998</mass>
        <inertia>
          <ixx>0.0052562499999999988</ixx>
          <ixy>0</ixy>
          <ixz>0.00056250000000000007</ixz>
          <iyy>0.0059312499999999964</iyy>
          <iyz>0</iyz>
          <izz>0.0082749999999999976</izz>
        </inertia>
      </inertial>
      <collision name='base_link_fixed_joint_lump__chassis_collision'>
        <pose>0.049999999999999989 0 0.074999999999999997 0 0 0</pose>
        <geometry>
          <box>
            <size>0.29999999999999999 0.29999999999999999 0.14999999999999999</size>
          </box>
        </geometry>
        <surface>
          <contact>
            <ode/>
          </contact>
          <friction>
            <ode/>
          </friction>
        </surface>
      </collision>
      <collision name='base_link_fixed_joint_lump__caster_wheel_collision_1'>
        <pose>0.14000000000000001 0 0 0 0 0</pose>
        <geometry>
          <sphere>
            <radius>0.050000000000000003</radius>
          </sphere>
        </geometry>
        <surface>
          <contact>
            <ode/>
          </contact>
          <friction>
            <ode>
              <mu>0.001</mu>
              <mu2>0.001</mu2>
            </ode>
          </friction>
        </surface>
      </collision>
      <visual name='base_link_fixed_joint_lump__chassis_visual'>
        <pose>0.049999999999999989 0 0.074999999999999997 0 0 0</pose>
        <geometry>
          <box>
            <size>0.29999999999999999 0.29999999999999999 0.14999999999999999</size>
          </box>
        </geometry>
        <material>
          <script>
            <name>Gazebo/White</name>
            <uri>file://media/materials/scripts/gazebo.material</uri>
          </script>
          <diffuse>1 1 1 1</diffuse>
          <ambient>1 1 1 1</ambient>
        </material>
      </visual>
      <visual name='base_link_fixed_joint_lump__caster_wheel_visual_1'>
        <pose>0.14000000000000001 0 0 0 0 0</pose>
        <geometry>
          <sphere>
            <radius>0.050000000000000003</radius>
          </sphere>
        </geometry>
        <material>
          <script>
            <name>Gazebo/Black</name>
            <uri>file://media/materials/scripts/gazebo.material</uri>
          </script>
          <diffuse>0 0 0 1</diffuse>
          <ambient>0 0 0 1</ambient>
        </material>
      </visual>
    </link>
    <joint name='left_wheel_joint' type='revolute'>
      <pose relative_to='base_link'>0 0.17499999999999999 0 -1.5707963267948959 0 0</pose>
      <parent>base_link</parent>
      <child>left_wheel</child>
      <axis>
        <xyz>0 0 1</xyz>
        <limit>
          <lower>-inf</lower>
          <upper>inf</upper>
        </limit>
        <dynamics>
          <spring_reference>0</spring_reference>
          <spring_stiffness>0</spring_stiffness>
        </dynamics>
      </axis>
    </joint>
    <link name='left_wheel'>
      <pose relative_to='left_wheel_joint'>0 0 0 0 0 0</pose>
      <inertial>
        <pose>0 0 0 0 0 0</pose>
        <mass>0.10000000000000001</mass>
        <inertia>
          <ixx>7.5833333333333352e-05</ixx>
          <ixy>0</ixy>
          <ixz>0</ixz>
          <iyy>7.5833333333333352e-05</iyy>
          <iyz>0</iyz>
          <izz>0.000125</izz>
        </inertia>
      </inertial>
      <collision name='left_wheel_collision'>
        <pose>0 0 0 0 0 0</pose>
        <geometry>
          <cylinder>
            <length>0.040000000000000001</length>
            <radius>0.050000000000000003</radius>
          </cylinder>
        </geometry>
        <surface>
          <contact>
            <ode/>
          </contact>
          <friction>
            <ode/>
          </friction>
        </surface>
      </collision>
      <visual name='left_wheel_visual'>
        <pose>0 0 0 0 0 0</pose>
        <geometry>
          <cylinder>
            <length>0.040000000000000001</length>
            <radius>0.050000000000000003</radius>
          </cylinder>
        </geometry>
        <material>
          <script>
            <name>Gazebo/Blue</name>
            <uri>file://media/materials/scripts/gazebo.material</uri>
          </script>
          <diffuse>0.25 0.25 1 1</diffuse>
          <ambient>0.25 0.25 1 1</ambient>
        </material>
      </visual>
    </link>
    <joint name='right_wheel_joint' type='revolute'>
      <pose relative_to='base_link'>0 -0.17499999999999999 0 1.5707963267948959 0 0</pose>
      <parent>base_link</parent>
      <child>right_wheel</child>
      <axis>
        <xyz>0 0 -1</xyz>
        <limit>
          <lower>-inf</lower>
          <upper>inf</upper>
        </limit>
        <dynamics>
          <spring_reference>0</spring_reference>
          <spring_stiffness>0</spring_stiffness>
        </dynamics>
      </axis>
    </joint>
    <link name='right_wheel'>
      <pose relative_to='right_wheel_joint'>0 0 0 0 0 0</pose>
      <inertial>
        <pose>0 0 0 0 0 0</pose>
        <mass>0.10000000000000001</mass>
        <inertia>
          <ixx>7.5833333333333352e-05</ixx>
          <ixy>0</ixy>
          <ixz>0</ixz>
          <iyy>7.5833333333333352e-05</iyy>
          <iyz>0</iyz>
          <izz>0.000125</izz>
        </inertia>
      </inertial>
      <collision name='right_wheel_collision'>
        <pose>0 0 0 0 0 0</pose>
        <geometry>
          <cylinder>
            <length>0.040000000000000001</length>
            <radius>0.050000000000000003</radius>
          </cylinder>
        </geometry>
        <surface>
          <contact>
            <ode/>
          </contact>
          <friction>
            <ode/>
          </friction>
        </surface>
      </collision>
      <visual name='right_wheel_visual'>
        <pose>0 0 0 0 0 0</pose>
        <geometry>
          <cylinder>
            <length>0.040000000000000001</length>
            <radius>0.050000000000000003</radius>
          </cylinder>
        </geometry>
        <material>
          <script>
            <name>Gazebo/Blue</name>
            <uri>file://media/materials/scripts/gazebo.material</uri>
          </script>
          <diffuse>0.25 0.25 1 1</diffuse>
          <ambient>0.25 0.25 1 1</ambient>
        </material>
      </visual>
    </link>
    <frame name='caster_wheel_joint' attached_to='chassis'>
      <pose>0.23999999999999999 0 0 0 0 0</pose>
    </frame>
    <frame name='caster_wheel' attached_to='caster_wheel_joint'>
      <pose>0 0 0 0 0 0</pose>
    </frame>
    <frame name='chassis_joint' attached_to='base_link'>
      <pose>-0.10000000000000001 0 0 0 0 0</pose>
    </frame>
    <frame name='chassis' attached_to='chassis_joint'>
      <pose>0 0 0 0 0 0</pose>
    </frame>
    <plugin name="gz::sim::systems::DiffDrive" filename="gz-sim-diff-drive-system">
        <left_joint>left_wheel_joint</left_joint>
        <right_joint>right_wheel_joint</right_joint>
        <wheel_separation>0.35</wheel_separation>
        <wheel_radius>0.05</wheel_radius>
        <odom_publish_frequency>1</odom_publish_frequency>
        <max_linear_acceleration>5.0</max_linear_acceleration>
        <min_linear_acceleration>-5.0</min_linear_acceleration>
        <max_angular_acceleration>2</max_angular_acceleration>
        <min_angular_acceleration>-2</min_angular_acceleration>
        <max_linear_velocity>2.5</max_linear_velocity>
        <min_linear_velocity>-2.5</min_linear_velocity>
        <max_angular_velocity>1</max_angular_velocity>
        <min_angular_velocity>-1</min_angular_velocity>
      </plugin>
  </model>
</sdf>